ubuntu@HaskellUbuntu:~/workspace/OS-Assignment/ossim_source_code_part2_hk231_paging$ ./os os_1_mlq_paging_small_1K
Time slot   0
ld_routine
Time slot   1
	Loaded a process at input/proc/p0s, PID: 1 PRIO: 130
Time slot   2
	CPU 3: Dispatched process  1
	Loaded a process at input/proc/s3, PID: 2 PRIO: 39
Time slot   3
	CPU 2: Dispatched process  2
Time slot   4
	Loaded a process at input/proc/m1s, PID: 3 PRIO: 15
	CPU 3: Put process  1 to run queue
	CPU 3: Dispatched process  3
Time slot   5
	CPU 0: Dispatched process  1
	CPU 2: Put process  2 to run queue
	CPU 2: Dispatched process  2
Time slot   6
	CPU 3: Put process  3 to run queue
	CPU 3: Dispatched process  3
	Loaded a process at input/proc/s2, PID: 4 PRIO: 120
	CPU 2: Put process  2 to run queue
	CPU 2: Dispatched process  2
	CPU 0: Put process  1 to run queue
	CPU 0: Dispatched process  1
	CPU 1: Dispatched process  4
Time slot   7
	Loaded a process at input/proc/m0s, PID: 5 PRIO: 120
Time slot   8
	CPU 3: Put process  3 to run queue
	CPU 3: Dispatched process  3
PID=1 write region=1 offset=20 value=100
print_pgtbl: 0 - 1024
00000000: 80000001
00000004: 80000000
00000008: 80000005
00000012: 80000004
Write address 64
Start memphy dump
Address=64, Value=100
Time slot   9
	Loaded a process at input/proc/p1s, PID: 6 PRIO: 15
	CPU 1: Put process  4 to run queue
	CPU 2: Put process  2 to run queue
	CPU 2: Dispatched process  2
	CPU 1: Dispatched process  6
	CPU 0: Put process  1 to run queue
	CPU 0: Dispatched process  5
Time slot  10
	CPU 3: Put process  3 to run queue
	CPU 3: Dispatched process  3
Time slot  11
	CPU 2: Put process  2 to run queue
	CPU 2: Dispatched process  2
	CPU 0: Put process  5 to run queue
	CPU 0: Dispatched process  5
	Loaded a process at input/proc/s0, PID: 7 PRIO: 38
	CPU 1: Put process  6 to run queue
	CPU 1: Dispatched process  6
Time slot  12
	CPU 3: Processed  3 has finished
	CPU 3: Dispatched process  7
Time slot  13
	CPU 2: Put process  2 to run queue
	CPU 2: Dispatched process  2
	CPU 0: Put process  5 to run queue
	CPU 1: Put process  6 to run queue
	CPU 1: Dispatched process  6
	CPU 0: Dispatched process  5
PID=5 write region=1 offset=20 value=102
print_pgtbl: 0 - 512
00000000: 80000000
00000004: 80000001
Write address 320
Start memphy dump
Address=64, Value=100
Address=320, Value=102
Time slot  14
	CPU 2: Processed  2 has finished
	CPU 3: Put process  7 to run queue
	CPU 3: Dispatched process  7
PID=5 write region=2 offset=1000 value=1
print_pgtbl: 0 - 512
00000000: 80000000
00000004: 80000001
Offset out of region's range. Fail to write to this address!
	CPU 2: Dispatched process  4
Time slot  15
	CPU 0: Put process  5 to run queue
	CPU 0: Dispatched process  5
PID=5 write region=0 offset=0 value=0
print_pgtbl: 0 - 512
00000000: 80000000
00000004: 80000001
Write address  0
Start memphy dump
Address= 0, Value=0
Address=64, Value=100
Address=320, Value=102
	CPU 1: Put process  6 to run queue
	CPU 1: Dispatched process  6
Time slot  16
	CPU 2: Put process  4 to run queue
	CPU 2: Dispatched process  4
	Loaded a process at input/proc/s1, PID: 8 PRIO: 0
	CPU 3: Put process  7 to run queue
	CPU 0: Processed  5 has finished
	CPU 0: Dispatched process  7
	CPU 3: Dispatched process  8
Time slot  17
	CPU 1: Put process  6 to run queue
	CPU 1: Dispatched process  6
Time slot  18
	CPU 3: Put process  8 to run queue
	CPU 3: Dispatched process  8
	CPU 2: Put process  4 to run queue
	CPU 2: Dispatched process  4
	CPU 0: Put process  7 to run queue
	CPU 0: Dispatched process  7
Time slot  19
	CPU 1: Processed  6 has finished
	CPU 1: Dispatched process  1
Read address 832
PID=1 read region=1 offset=20 value=100
print_pgtbl: 0 - 1024
00000000: c0000000
00000004: 80000003
00000008: 80000005
00000012: 80000004
Start memphy dump
Address= 0, Value=0
Address=64, Value=100
Address=320, Value=102
Address=832, Value=100
Time slot  20
	CPU 3: Put process  8 to run queue
	CPU 3: Dispatched process  8
	CPU 0: Put process  7 to run queue
	CPU 0: Dispatched process  7
PID=1 write region=2 offset=20 value=102
print_pgtbl: 0 - 1024
00000000: c0000000
00000004: 80000003
00000008: 80000005
00000012: 80000004
	CPU 2: Put process  4 to run queue
	CPU 2: Dispatched process  4
Write address 932
Start memphy dump
Address= 0, Value=0
Address=64, Value=100
Address=320, Value=102
Address=832, Value=100
Address=932, Value=102
Time slot  21
	CPU 1: Put process  1 to run queue
	CPU 1: Dispatched process  1
Read address 932
PID=1 read region=2 offset=20 value=102
print_pgtbl: 0 - 1024
00000000: c0000000
00000004: 80000003
00000008: 80000005
00000012: 80000004
Start memphy dump
Address= 0, Value=0
Address=64, Value=100
Address=320, Value=102
Address=832, Value=100
Address=932, Value=102
Time slot  22
	CPU 2: Put process  4 to run queue
	CPU 2: Dispatched process  4
	CPU 3: Put process  8 to run queue
	CPU 0: Put process  7 to run queue
	CPU 0: Dispatched process  7
	CPU 3: Dispatched process  8
PID=1 write region=3 offset=20 value=103
print_pgtbl: 0 - 1024
00000000: c0000000
00000004: 80000003
00000008: 80000005
00000012: 80000004
Write address 1088
Start memphy dump
Address= 0, Value=0
Address=64, Value=100
Address=320, Value=102
Address=832, Value=100
Address=932, Value=102
Address=1088, Value=103
Time slot  23
	CPU 3: Processed  8 has finished
	CPU 3 stopped
	CPU 1: Processed  1 has finished
	CPU 1 stopped
Time slot  24
	CPU 0: Put process  7 to run queue
	CPU 0: Dispatched process  7
	CPU 2: Processed  4 has finished
	CPU 2 stopped
Time slot  25
Time slot  26
	CPU 0: Put process  7 to run queue
	CPU 0: Dispatched process  7
Time slot  27
	CPU 0: Processed  7 has finished
	CPU 0 stopped

